Workbook

Sheet MADINAH Migration Plan
B2: MADINAH Migration Flow | C2: Activity | D2: 46113 | E2: 46143 | F2: 46174 | G2: 46204 | H2: 46235 | I2: 46266 | J2: 46296 | K2: Remark
C3: Database Migration (1st Round) (20-May-26) | K3: Madinah Database Migration (1st Round) completed
C4: SLD 1st patch (10 SS) | K4: SLD 1st patch in Madinah: (to be confirmed by CET)
C5: Validation by SE | K5: 3 days FF with SLD 1st patch
C6: E2E for 1st patch (10 SS - 20 points) | K6: Start 18-Jun Finish: 21-Jun Depend on Telecom Readiness
C7: SLD 2nd patch | K7: Start: 23-May Finish: 30-May
C8: SLD 3rd patch | K8: Start: 01-Jun Finish: 08-Jun
C9: SLD 4th patch | K9: Start: 01-Jun Finish: 08-Jun
C10: SLD 5th patch | K10: Start: 01-Jun Finish: 08-Jun
C11: SLD 6th patch | K11: Start: 09-Jun Finish: 16-Jun
C12: SLD 7th patch | K12: Start: 09-Jun Finish: 16-Jun
C13: SLD 8th patch | K13: Start: 09-Jun Finish: 16-Jun
C14: SLD 9th patch | K14: Start: 17-Jun Finish: 24-Jun
... C28: Regression test | K28: 1 day
C29: Training inside KSA
C30: Training in China
C31: DERMS Software Installation shall start by 19-May-26 (Madinah) | K31: OT switches shall be mobilized by 16-May
C32: DERMS SAT

Sheet Progress Summary
A1: 0 | B1: Not Strated | C1: Not Strated | D1: SDCC - Overall Upstream Progress
A2: 0.5 | B2: In Progress | C2: In Progress
A3: 1 | B3: Completed | C3: Completed
A5: MADINAH Upstream Progress | J5: JEDDAH Upstream Progress | S5: MAKKAH Upstream Progress
A6: Batch No. | B6: Planned % | C6: Completed % | D6: SLD Submission | E6: SLD Validation | F6: E2E for Grid SS | G6: E2E Rectification | H6: Cutover | J6: Batch No. | K6: Planned % | L6: Completed % | M6: SLD Submission | N6: SLD Validation | O6: E2E for Grid SS | P6: E2E Rectification | Q6: Cutover | S6: Batch No. | T6: Planned % | U6: Completed % | V6: SLD Submission | W6: SLD Validation | X6: E2E for Grid SS | Y6: E2E Rectification | Z6: Cutover | AC6: -
A7: Batch 01 | B7: {=IFERROR(AVERAGE(_xlfn._xlws.FILTER(IF(TODAY()<'MADINAH Migration Plan-'!$E$2:$E$205,0,IF(TODAY()>='MADINAH Migration Plan-'!$F$2:$F$205,1,NETWORKDAYS.INTL('MADINAH Migration Plan-'!$E$2:$E$205,TODAY(),"0000011")/NETWORKDAYS.INTL('MADINAH Migration Plan-'!$E$2:$E$205,'MADINAH Migration Plan-'!$F$2:$F$205,"0000011"))),('MADINAH Migration Plan-'!$Y$2:$Y$205=$A7)*('MADINAH Migration Plan-'!$E$2:$E$205<>"")*('MADINAH Migration Plan-'!$F$2:$F$205<>""))),0)} -> 0 | C7: =AVERAGE(D7:H7) -> 0.2 | D7: {=IFERROR(INDEX('MADINAH Migration Plan-'!$K:$K,MATCH(1,('MADINAH Migration Plan-'!$Y:$Y=$A7)*('MADINAH Migration Plan-'!$X:$X=D$6),0)),0)} -> 1 | E7: {=IFERROR(INDEX('MADINAH Migration Plan-'!$K:$K,MATCH(1,('MADINAH Migration Plan-'!$Y:$Y=$A7)*('MADINAH Migration Plan-'!$X:$X=E$6),0)),0)} -> 0 | F7: {=IFERROR(INDEX('MADINAH Migration Plan-'!$K:$K,MATCH(1,('MADINAH Migration Plan-'!$Y:$Y=$A7)*('MADINAH Migration Plan-'!$X:$X=F$6),0)),0)} -> 0 | G7: {=IFERROR(INDEX('MADINAH Migration Plan-'!$K:$K,MATCH(1,('MADINAH Migration Plan-'!$Y:$Y=$A7)*('MADINAH Migration Plan-'!$X:$X=G$6),0)),0)} -> 0 | H7: {=IFERROR(INDEX('MADINAH Migration Plan-'!$K:$K,MATCH(1,('MADINAH Migration Plan-'!$Y:$Y=$A7)*('MADINAH Migration Plan-'!$X:$X=H$6),0)),0)} -> 0 | J7: Batch 01 | K7: {=IFERROR(AVERAGE(_xlfn._xlws.FILTER(IF(TODAY()<'Jeddah Migration Plan'!$E$2:$E$207,0,IF(TODAY()>='Jeddah Migration Plan'!$F$2:$F$207,1,NETWORKDAYS.INTL('Jeddah Migration Plan'!$E$2:$E$207,TODAY(),"0000011")/NETWORKDAYS.INTL('Jeddah Migration Plan'!$E$2:$E$207,'Jeddah Migration Plan'!$F$2:$F$207,"0000011"))),('Jeddah Migration Plan'!$Y$2:$Y$207=$J7)*('Jeddah Migration Plan'!$E$2:$E$207<>"")*('Jeddah Migration Plan'!$F$2:$F$207<>""))),0)} -> 0 | L7: =AVERAGE(M7:Q7) -> 0.18 | M7: {=IFERROR(INDEX('Jeddah Migration Plan'!$K:$K,MATCH(1,('Jeddah Migration Plan'!$Y:$Y=$J7)*('Jeddah Migration Plan'!$X:$X=M$6),0)),0)} -> 0.9 | N7: {=IFERROR(INDEX('Jeddah Migration Plan'!$K:$K,MATCH(1,('Jeddah Migration Plan'!$Y:$Y=$J7)*('Jeddah Migration Plan'!$X:$X=N$6),0)),0)} -> 0 | O7: {=IFERROR(INDEX('Jeddah Migration Plan'!$K:$K,MATCH(1,('Jeddah Migration Plan'!$Y:$Y=$J7)*('Jeddah Migration Plan'!$X:$X=O$6),0)),0)} -> 0 | P7: {=IFERROR(INDEX('Jeddah Migration Plan'!$K:$K,MATCH(1,('Jeddah Migration Plan'!$Y:$Y=$J7)*('Jeddah Migration Plan'!$X:$X=P$6),0)),0)} -> 0 | Q7: {=IFERROR(INDEX('Jeddah Migration Plan'!$K:$K,MATCH(1,('Jeddah Migration Plan'!$Y:$Y=$J7)*('Jeddah Migration Plan'!$X:$X=Q$6),0)),0)} -> 0 | S7: Batch 01 | T7: {=IFERROR(AVERAGE(_xlfn._xlws.FILTER(IF(TODAY()<'Makkah Migration Plan'!$E$2:$E$204,0,IF(TODAY()>='Makkah Migration Plan'!$F$2:$F$204,1,NETWORKDAYS.INTL('Makkah Migration Plan'!$E$2:$E$204,TODAY(),"0000011")/NETWORKDAYS.INTL('Makkah Migration Plan'!$E$2:$E$204,'Makkah Migration Plan'!$F$2:$F$204,"0000011"))),('Makkah Migration Plan'!$Y$2:$Y$204=$S7)*('Makkah Migration Plan'!$E$2:$E$204<>"")*('Makkah Migration Plan'!$F$2:$F$204<>""))),0)} -> 0 | U7: =AVERAGE(V7:Z7) -> 0.18 | V7: {=IFERROR(INDEX('Makkah Migration Plan'!$K:$K,MATCH(1,('Makkah Migration Plan'!$Y:$Y=$S20)*('Makkah Migration Plan'!$X:$X=V$19),0)),0)} -> 0.9 | W7: {=IFERROR(INDEX('Makkah Migration Plan'!$K:$K,MATCH(1,('Makkah Migration Plan'!$Y:$Y=$S20)*('Makkah Migration Plan'!$X:$X=W$19),0)),0)} -> 0 | X7: {=IFERROR(INDEX('Makkah Migration Plan'!$K:$K,MATCH(1,('Makkah Migration Plan'!$Y:$Y=$S20)*('Makkah Migration Plan'!$X:$X=X$19),0)),0)} -> 0 | Y7: {=IFERROR(INDEX('Makkah Migration Plan'!$K:$K,MATCH(1,('Makkah Migration Plan'!$Y:$Y=$S20)*('Makkah Migration Plan'!$X:$X=Y$19),0)),0)} -> 0 | Z7: {=IFERROR(INDEX('Makkah Migration Plan'!$K:$K,MATCH(1,('Makkah Migration Plan'!$Y:$Y=$S20)*('Makkah Migration Plan'!$X:$X=Z$19),0)),0)} -> 0
A8: Batch 02 | B8: {=IFERROR(AVERAGE(_xlfn._xlws.FILTER(IF(TODAY()<'MADINAH Migration Plan-'!$E$2:$E$205,0,IF(TODAY()>='MADINAH Migration Plan-'!$F$2:$F$205,1,NETWORKDAYS.INTL('MADINAH Migration Plan-'!$E$2:$E$205,TODAY(),"0000011")/NETWORKDAYS.INTL('MADINAH Migration Plan-'!$E$2:$E$205,'MADINAH Migration Plan-'!$F$2:$F$205,"0000011"))),('MADINAH Migration Plan-'!$Y$2:$Y$205=$A8)*('MADINAH Migration Plan-'!$E$2:$E$205<>"")*('MADINAH Migration Plan-'!$F$2:$F$205<>""))),0)} -> 0.2 | C8: =AVERAGE(D8:H8) -> 0.2 | D8: {=IFERROR(INDEX('MADINAH Migration Plan-'!$K:$K,MATCH(1,('MADINAH Migration Plan-'!$Y:$Y=$A8)*('MADINAH Migration Plan-'!$X:$X=D$6),0)),0)} -> 1 | E8: {=IFERROR(INDEX('MADINAH Migration Plan-'!$K:$K,MATCH(1,('MADINAH Migration Plan-'!$Y:$Y=$A8)*('MADINAH Migration Plan-'!$X:$X=E$6),0)),0)} -> 0 | F8: {=IFERROR(INDEX('MADINAH Migration Plan-'!$K:$K,MATCH(1,('MADINAH Migration Plan-'!$Y:$Y=$A8)*('MADINAH Migration Plan-'!$X:$X=F$6),0)),0)} -> 0 | G8: {=IFERROR(INDEX('MADINAH Migration Plan-'!$K:$K,MATCH(1,('MADINAH Migration Plan-'!$Y:$Y=$A8)*('MADINAH Migration Plan-'!$X:$X=G$6),0)),0)} -> 0 | H8: {=IFERROR(INDEX('MADINAH Migration Plan-'!$K:$K,MATCH(1,('MADINAH Migration Plan-'!$Y:$Y=$A8)*('MADINAH Migration Plan-'!$X:$X=H$6),0)),0)} -> 0 | J8: Batch 02 | K8: {=IFERROR(AVERAGE(_xlfn._xlws.FILTER(IF(TODAY()<'Jeddah Migration Plan'!$E$2:$E$207,0,IF(TODAY()>='Jeddah Migration Plan'!$F$2:$F$207,1,NETWORKDAYS.INTL('Jeddah Migration Plan'!$E$2:$E$207,TODAY(),"0000011")/NETWORKDAYS.INTL('Jeddah Migration Plan'!$E$2:$E$207,'Jeddah Migration Plan'!$F$2:$F$207,"0000011"))),('Jeddah Migration Plan'!$Y$2:$Y$207=$J8)*('Jeddah Migration Plan'!$E$2:$E$207<>"")*('Jeddah Migration Plan'!$F$2:$F$207<>""))),0)} -> 0 | L8: =AVERAGE(M8:Q8) -> 0.18 | M8: {=IFERROR(INDEX('Jeddah Migration Plan'!$K:$K,MATCH(1,('Jeddah Migration Plan'!$Y:$Y=$J8)*('Jeddah Migration Plan'!$X:$X=M$6),0)),0)} -> 0.9 | N8: {=IFERROR(INDEX('Jeddah Migration Plan'!$K:$K,MATCH(1,('Jeddah Migration Plan'!$Y:$Y=$J8)*('Jeddah Migration Plan'!$X:$X=N$6),0)),0)} -> 0 | O8: {=IFERROR(INDEX('Jeddah Migration Plan'!$K:$K,MATCH(1,('Jeddah Migration Plan'!$Y:$Y=$J8)*('Jeddah Migration Plan'!$X:$X=O$6),0)),0)} -> 0 | P8: {=IFERROR(INDEX('Jeddah Migration Plan'!$K:$K,MATCH(1,('Jeddah Migration Plan'!$Y:$Y=$J8)*('Jeddah Migration Plan'!$X:$X=P$6),0)),0)} -> 0 | Q8: {=IFERROR(INDEX('Jeddah Migration Plan'!$K:$K,MATCH(1,('Jeddah Migration Plan'!$Y:$Y=$J8)*('Jeddah Migration Plan'!$X:$X=Q$6),0)),0)} -> 0 | S8: Batch 02 | T8: {=IFERROR(AVERAGE(_xlfn._xlws.FILTER(IF(TODAY()<'Makkah Migration Plan'!$E$2:$E$204,0,IF(TODAY()>='Makkah Migration Plan'!$F$2:$F$204,1,NETWORKDAYS.INTL('Makkah Migration Plan'!$E$2:$E$204,TODAY(),"0000011")/NETWORKDAYS.INTL('Makkah Migration Plan'!$E$2:$E$204,'Makkah Migration Plan'!$F$2:$F$204,"0000011"))),('Makkah Migration Plan'!$Y$2:$Y$204=$S8)*('Makkah Migration Plan'!$E$2:$E$204<>"")*('Makkah Migration Plan'!$F$2:$F$204<>""))),0)} -> 0 | U8: =AVERAGE(V8:Z8) -> 0.18 | V8: {=IFERROR(INDEX('Makkah Migration Plan'!$K:$K,MATCH(1,('Makkah Migration Plan'!$Y:$Y=$S21)*('Makkah Migration Plan'!$X:$X=V$19),0)),0)} -> 0.9 | W8: {=IFERROR(INDEX('Makkah Migration Plan'!$K:$K,MATCH(1,('Makkah Migration Plan'!$Y:$Y=$S21)*('Makkah Migration Plan'!$X:$X=W$19),0)),0)} -> 0 | X8: {=IFERROR(INDEX('Makkah Migration Plan'!$K:$K,MATCH(1,('Makkah Migration Plan'!$Y:$Y=$S21)*('Makkah Migration Plan'!$X:$X=X$19),0)),0)} -> 0 | Y8: {=IFERROR(INDEX('Makkah Migration Plan'!$K:$K,MATCH(1,('Makkah Migration Plan'!$Y:$Y=$S21)*('Makkah Migration Plan'!$X:$X=Y$19),0)),0)} -> 0 | Z8: {=IFERROR(INDEX('Makkah Migration Plan'!$K:$K,MATCH(1,('Makkah Migration Plan'!$Y:$Y=$S21)*('Makkah Migration Plan'!$X:$X=Z$19),0)),0)} -> 0
A9: Batch 03 | B9: {=IFERROR(AVERAGE(_xlfn._xlws.FILTER(IF(TODAY()<'MADINAH Migration Plan-'!$E$2:$E$205,0,IF(TODAY()>='MADINAH Migration Plan-'!$F$2:$F$205,1,NETWORKDAYS.INTL('MADINAH Migration Plan-'!$E$2:$E$205,TODAY(),"0000011")/NETWORKDAYS.INTL('MADINAH Migration Plan-'!$E$2:$E$205,'MADINAH Migration Plan-'!$F$2:$F$205,"0000011"))),('MADINAH Migration Plan-'!$Y$2:$Y$205=$A9)*('MADINAH Migration Plan-'!$E$2:$E$205<>"")*('MADINAH Migration Plan-'!$F$2:$F$205<>""))),0)} -> 0.2 | C9: =AVERAGE(D9:H9) -> 0.18 | D9: {=IFERROR(INDEX('MADINAH Migration Plan-'!$K:$K,MATCH(1,('MADINAH Migration Plan-'!$Y:$Y=$A9)*('MADINAH Migration Plan-'!$X:$X=D$6),0)),0)} -> 0.9 | E9: {=IFERROR(INDEX('MADINAH Migration Plan-'!$K:$K,MATCH(1,('MADINAH Migration Plan-'!$Y:$Y=$A9)*('MADINAH Migration Plan-'!$X:$X=E$6),0)),0)} -> 0 | F9: {=IFERROR(INDEX('MADINAH Migration Plan-'!$K:$K,MATCH(1,('MADINAH Migration Plan-'!$Y:$Y=$A9)*('MADINAH Migration Plan-'!$X:$X=F$6),0)),0)} -> 0 | G9: {=IFERROR(INDEX('MADINAH Migration Plan-'!$K:$K,MATCH(1,('MADINAH Migration Plan-'!$Y:$Y=$A9)*('MADINAH Migration Plan-'!$X:$X=G$6),0)),0)} -> 0 | H9: {=IFERROR(INDEX('MADINAH Migration Plan-'!$K:$K,MATCH(1,('MADINAH Migration Plan-'!$Y:$Y=$A9)*('MADINAH Migration Plan-'!$X:$X=H$6),0)),0)} -> 0 | J9: Batch 03 | K9: {=IFERROR(AVERAGE(_xlfn._xlws.FILTER(IF(TODAY()<'Jeddah Migration Plan'!$E$2:$E$207,0,IF(TODAY()>='Jeddah Migration Plan'!$F$2:$F$207,1,NETWORKDAYS.INTL('Jeddah Migration Plan'!$E$2:$E$207,TODAY(),"0000011")/NETWORKDAYS.INTL('Jeddah Migration Plan'!$E$2:$E$207,'Jeddah Migration Plan'!$F$2:$F$207,"0000011"))),('Jeddah Migration Plan'!$Y$2:$Y$207=$J9)*('Jeddah Migration Plan'!$E$2:$E$207<>"")*('Jeddah Migration Plan'!$F$2:$F$207<>""))),0)} -> 0 | L9: =AVERAGE(M9:Q9) -> 0.084 | M9: {=IFERROR(INDEX('Jeddah Migration Plan'!$K:$K,MATCH(1,('Jeddah Migration Plan'!$Y:$Y=$J9)*('Jeddah Migration Plan'!$X:$X=M$6),0)),0)} -> 0.42 | N9: {=IFERROR(INDEX('Jeddah Migration Plan'!$K:$K,MATCH(1,('Jeddah Migration Plan'!$Y:$Y=$J9)*('Jeddah Migration Plan'!$X:$X=N$6),0)),0)} -> 0 | O9: {=IFERROR(INDEX('Jeddah Migration Plan'!$K:$K,MATCH(1,('Jeddah Migration Plan'!$Y:$Y=$J9)*('Jeddah Migration Plan'!$X:$X=O$6),0)),0)} -> 0 | P9: {=IFERROR(INDEX('Jeddah Migration Plan'!$K:$K,MATCH(1,('Jeddah Migration Plan'!$Y:$Y=$J9)*('Jeddah Migration Plan'!$X:$X=P$6),0)),0)} -> 0 | Q9: {=IFERROR(INDEX('Jeddah Migration Plan'!$K:$K,MATCH(1,('Jeddah Migration Plan'!$Y:$Y=$J9)*('Jeddah Migration Plan'!$X:$X=Q$6),0)),0)} -> 0 | S9: Batch 03 | T9: {=IFERROR(AVERAGE(_xlfn._xlws.FILTER(IF(TODAY()<'Makkah Migration Plan'!$E$2:$E$204,0,IF(TODAY()>='Makkah Migration Plan'!$F$2:$F$204,1,NETWORKDAYS.INTL('Makkah Migration Plan'!$E$2:$E$204,TODAY(),"0000011")/NETWORKDAYS.INTL('Makkah Migration Plan'!$E$2:$E$204,'Makkah Migration Plan'!$F$2:$F$204,"0000011"))),('Makkah Migration Plan'!$Y$2:$Y$204=$S9)*('Makkah Migration Plan'!$E$2:$E$204<>"")*('Makkah Migration Plan'!$F$2:$F$204<>""))),0)} -> 0 | U9: =AVERAGE(V9:Z9) -> 0.186 | V9: {=IFERROR(INDEX('Makkah Migration Plan'!$K:$K,MATCH(1,('Makkah Migration Plan'!$Y:$Y=$S22)*('Makkah Migration Plan'!$X:$X=V$19),0)),0)} -> 0.93 | W9: {=IFERROR(INDEX('Makkah Migration Plan'!$K:$K,MATCH(1,('Makkah Migration Plan'!$Y:$Y=$S22)*('Makkah Migration Plan'!$X:$X=W$19),0)),0)} -> 0 | X9: {=IFERROR(INDEX('Makkah Migration Plan'!$K:$K,MATCH(1,('Makkah Migration Plan'!$Y:$Y=$S22)*('Makkah Migration Plan'!$X:$X=X$19),0)),0)} -> 0 | Y9: {=IFERROR(INDEX('Makkah Migration Plan'!$K:$K,MATCH(1,('Makkah Migration Plan'!$Y:$Y=$S22)*('Makkah Migration Plan'!$X:$X=Y$19),0)),0)} -> 0 | Z9: {=IFERROR(INDEX('Makkah Migration Plan'!$K:$K,MATCH(1,('Makkah Migration Plan'!$Y:$Y=$S22)*('Makkah Migration Plan'!$X:$X=Z$19),0)),0)} -> 0
A10: Batch 04 | B10: {=IFERROR(AVERAGE(_xlfn._xlws.FILTER(IF(TODAY()<'MADINAH Migration Plan-'!$E$2:$E$205,0,IF(TODAY()>='MADINAH Migration Plan-'!$F$2:$F$205,1,NETWORKDAYS.INTL('MADINAH Migration Plan-'!$E$2:$E$205,TODAY(),"0000011")/NETWORKDAYS.INTL('MADINAH Migration Plan-'!$E$2:$E$205,'MADINAH Migration Plan-'!$F$2:$F$205,"0000011"))),('MADINAH Migration Plan-'!$Y$2:$Y$205=$A10)*('MADINAH Migration Plan-'!$E$2:$E$205<>"")*('MADINAH Migration Plan-'!$F$2:$F$205<>""))),0)} -> 0 | C10: =AVERAGE(D10:H10) -> 0 | D10: {=IFERROR(INDEX('MADINAH Migration Plan-'!$K:$K,MATCH(1,('MADINAH Migration Plan-'!$Y:$Y=$A10)*('MADINAH Migration Plan-'!$X:$X=D$6),0)),0)} -> 0 | E10: {=IFERROR(INDEX('MADINAH Migration Plan-'!$K:$K,MATCH(1,('MADINAH Migration Plan-'!$Y:$Y=$A10)*('MADINAH Migration Plan-'!$X:$X=E$6),0)),0)} -> 0 | F10: {=IFERROR(INDEX('MADINAH Migration Plan-'!$K:$K,MATCH(1,('MADINAH Migration Plan-'!$Y:$Y=$A10)*('MADINAH Migration Plan-'!$X:$X=F$6),0)),0)} -> 0 | G10: {=IFERROR(INDEX('MADINAH Migration Plan-'!$K:$K,MATCH(1,('MADINAH Migration Plan-'!$Y:$Y=$A10)*('MADINAH Migration Plan-'!$X:$X=G$6),0)),0)} -> 0 | H10: {=IFERROR(INDEX('MADINAH Migration Plan-'!$K:$K,MATCH(1,('MADINAH Migration Plan-'!$Y:$Y=$A10)*('MADINAH Migration Plan-'!$X:$X=H$6),0)),0)} -> 0 | J10: Batch 04 | K10: {=IFERROR(AVERAGE(_xlfn._xlws.FILTER(IF(TODAY()<'Jeddah Migration Plan'!$E$2:$E$207,0,IF(TODAY()>='Jeddah Migration Plan'!$F$2:$F$207,1,NETWORKDAYS.INTL('Jeddah Migration Plan'!$E$2:$E$207,TODAY(),"0000011")/NETWORKDAYS.INTL('Jeddah Migration Plan'!$E$2:$E$207,'Jeddah Migration Plan'!$F$2:$F$207,"0000011"))),('Jeddah Migration Plan'!$Y$2:$Y$207=$J10)*('Jeddah Migration Plan'!$E$2:$E$207<>"")*('Jeddah Migration Plan'!$F$2:$F$207<>""))),0)} -> 0 | L10: =AVERAGE(M10:Q10) -> 0 | M10: {=IFERROR(INDEX('Jeddah Migration Plan'!$K:$K,MATCH(1,('Jeddah Migration Plan'!$Y:$Y=$J10)*('Jeddah Migration Plan'!$X:$X=M$6),0)),0)} -> 0 | N10: {=IFERROR(INDEX('Jeddah Migration Plan'!$K:$K,MATCH(1,('Jeddah Migration Plan'!$Y:$Y=$J10)*('Jeddah Migration Plan'!$X:$X=N$6),0)),0)} -> 0 | O10: {=IFERROR(INDEX('Jeddah Migration Plan'!$K:$K,MATCH(1,('Jeddah Migration Plan'!$Y:$Y=$J10)*('Jeddah Migration Plan'!$X:$X=O$6),0)),0)} -> 0 | P10: {=IFERROR(INDEX('Jeddah Migration Plan'!$K:$K,MATCH(1,('Jeddah Migration Plan'!$Y:$Y=$J10)*('Jeddah Migration Plan'!$X:$X=P$6),0)),0)} -> 0 | Q10: {=IFERROR(INDEX('Jeddah Migration Plan'!$K:$K,MATCH(1,('Jeddah Migration Plan'!$Y:$Y=$J10)*('Jeddah Migration Plan'!$X:$X=Q$6),0)),0)} -> 0 | S10: Batch 04 | T10: {=IFERROR(AVERAGE(_xlfn._xlws.FILTER(IF(TODAY()<'Makkah Migration Plan'!$E$2:$E$204,0,IF(TODAY()>='Makkah Migration Plan'!$F$2:$F$204,1,NETWORKDAYS.INTL('Makkah Migration Plan'!$E$2:$E$204,TODAY(),"0000011")/NETWORKDAYS.INTL('Makkah Migration Plan'!$E$2:$E$204,'Makkah Migration Plan'!$F$2:$F$204,"0000011"))),('Makkah Migration Plan'!$Y$2:$Y$204=$S10)*('Makkah Migration Plan'!$E$2:$E$204<>"")*('Makkah Migration Plan'!$F$2:$F$204<>""))),0)} -> 0 | U10: =AVERAGE(V10:Z10) -> 0 | V10: {=IFERROR(INDEX('Makkah Migration Plan'!$K:$K,MATCH(1,('Makkah Migration Plan'!$Y:$Y=$S23)*('Makkah Migration Plan'!$X:$X=V$19),0)),0)} -> 0 | W10: {=IFERROR(INDEX('Makkah Migration Plan'!$K:$K,MATCH(1,('Makkah Migration Plan'!$Y:$Y=$S23)*('Makkah Migration Plan'!$X:$X=W$19),0)),0)} -> 0 | X10: {=IFERROR(INDEX('Makkah Migration Plan'!$K:$K,MATCH(1,('Makkah Migration Plan'!$Y:$Y=$S23)*('Makkah Migration Plan'!$X:$X=X$19),0)),0)} -> 0 | Y10: {=IFERROR(INDEX('Makkah Migration Plan'!$K:$K,MATCH(1,('Makkah Migration Plan'!$Y:$Y=$S23)*('Makkah Migration Plan'!$X:$X=Y$19),0)),0)} -> 0 | Z10: {=IFERROR(INDEX('Makkah Migration Plan'!$K:$K,MATCH(1,('Makkah Migration Plan'!$Y:$Y=$S23)*('Makkah Migration Plan'!$X:$X=Z$19),0)),0)} -> 0
A11: Batch 05 | B11: {=IFERROR(AVERAGE(_xlfn._xlws.FILTER(IF(TODAY()<'MADINAH Migration Plan-'!$E$2:$E$205,0,IF(TODAY()>='MADINAH Migration Plan-'!$F$2:$F$205,1,NETWORKDAYS.INTL('MADINAH Migration Plan-'!$E$2:$E$205,TODAY(),"0000011")/NETWORKDAYS.INTL('MADINAH Migration Plan-'!$E$2:$E$205,'MADINAH Migration Plan-'!$F$2:$F$205,"0000011"))),('MADINAH Migration Plan-'!$Y$2:$Y$205=$A11)*('MADINAH Migration Plan-'!$E$2:$E$205<>"")*('MADINAH Migration Plan-'!$F$2:$F$205<>""))),0)} -> 0 | C11: =AVERAGE(D11:H11) -> 0 | D11: {=IFERROR(INDEX('MADINAH Migration Plan-'!$K:$K,MATCH(1,('MADINAH Migration Plan-'!$Y:$Y=$A11)*('MADINAH Migration Plan-'!$X:$X=D$6),0)),0)} -> 0 | E11: {=IFERROR(INDEX('MADINAH Migration Plan-'!$K:$K,MATCH(1,('MADINAH Migration Plan-'!$Y:$Y=$A11)*('MADINAH Migration Plan-'!$X:$X=E$6),0)),0)} -> 0 | F11: {=IFERROR(INDEX('MADINAH Migration Plan-'!$K:$K,MATCH(1,('MADINAH Migration Plan-'!$Y:$Y=$A11)*('MADINAH Migration Plan-'!$X:$X=F$6),0)),0)} -> 0 | G11: {=IFERROR(INDEX('MADINAH Migration Plan-'!$K:$K,MATCH(1,('MADINAH Migration Plan-'!$Y:$Y=$A11)*('MADINAH Migration Plan-'!$X:$X=G$6),0)),0)} -> 0 | H11: {=IFERROR(INDEX('MADINAH Migration Plan-'!$K:$K,MATCH(1,('MADINAH Migration Plan-'!$Y:$Y=$A11)*('MADINAH Migration Plan-'!$X:$X=H$6),0)),0)} -> 0 | J11: Batch 05 | K11: {=IFERROR(AVERAGE(_xlfn._xlws.FILTER(IF(TODAY()<'Jeddah Migration Plan'!$E$2:$E$207,0,IF(TODAY()>='Jeddah Migration Plan'!$F$2:$F$207,1,NETWORKDAYS.INTL('Jeddah Migration Plan'!$E$2:$E$207,TODAY(),"0000011")/NETWORKDAYS.INTL('Jeddah Migration Plan'!$E$2:$E$207,'Jeddah Migration Plan'!$F$2:$F$207,"0000011"))),('Jeddah Migration Plan'!$Y$2:$Y$207=$J11)*('Jeddah Migration Plan'!$E$2:$E$207<>"")*('Jeddah Migration Plan'!$F$2:$F$207<>""))),0)} -> 0 | L11: =AVERAGE(M11:Q11) -> 0 | M11: {=IFERROR(INDEX('Jeddah Migration Plan'!$K:$K,MATCH(1,('Jeddah Migration Plan'!$Y:$Y=$J11)*('Jeddah Migration Plan'!$X:$X=M$6),0)),0)} -> 0 | N11: {=IFERROR(INDEX('Jeddah Migration Plan'!$K:$K,MATCH(1,('Jeddah Migration Plan'!$Y:$Y=$J11)*('Jeddah Migration Plan'!$X:$X=N$6),0)),0)} -> 0 | O11: {=IFERROR(INDEX('Jeddah Migration Plan'!$K:$K,MATCH(1,('Jeddah Migration Plan'!$Y:$Y=$J11)*('Jeddah Migration Plan'!$X:$X=O$6),0)),0)} -> 0 | P11: {=IFERROR(INDEX('Jeddah Migration Plan'!$K:$K,MATCH(1,('Jeddah Migration Plan'!$Y:$Y=$J11)*('Jeddah Migration Plan'!$X:$X=P$6),0)),0)} -> 0 | Q11: {=IFERROR(INDEX('Jeddah Migration Plan'!$K:$K,MATCH(1,('Jeddah Migration Plan'!$Y:$Y=$J11)*('Jeddah Migration Plan'!$X:$X=Q$6),0)),0)} -> 0 | S11: Batch 05 | T11: {=IFERROR(AVERAGE(_xlfn._xlws.FILTER(IF(TODAY()<'Makkah Migration Plan'!$E$2:$E$204,0,IF(TODAY()>='Makkah Migration Plan'!$F$2:$F$204,1,NETWORKDAYS.INTL('Makkah Migration Plan'!$E$2:$E$204,TODAY(),"0000011")/NETWORKDAYS.INTL('Makkah Migration Plan'!$E$2:$E$204,'Makkah Migration Plan'!$F$2:$F$204,"0000011"))),('Makkah Migration Plan'!$Y$2:$Y$204=$S11)*('Makkah Migration Plan'!$E$2:$E$204<>"")*('Makkah Migration Plan'!$F$2:$F$204<>""))),0)} -> 0 | U11: =AVERAGE(V11:Z11) -> 0 | V11: {=IFERROR(INDEX('Makkah Migration Plan'!$K:$K,MATCH(1,('Makkah Migration Plan'!$Y:$Y=$S24)*('Makkah Migration Plan'!$X:$X=V$19),0)),0)} -> 0 | W11: {=IFERROR(INDEX('Makkah Migration Plan'!$K:$K,MATCH(1,('Makkah Migration Plan'!$Y:$Y=$S24)*('Makkah Migration Plan'!$X:$X=W$19),0)),0)} -> 0 | X11: {=IFERROR(INDEX('Makkah Migration Plan'!$K:$K,MATCH(1,('Makkah Migration Plan'!$Y:$Y=$S24)*('Makkah Migration Plan'!$X:$X=X$19),0)),0)} -> 0 | Y11: {=IFERROR(INDEX('Makkah Migration Plan'!$K:$K,MATCH(1,('Makkah Migration Plan'!$Y:$Y=$S24)*('Makkah Migration Plan'!$X:$X=Y$19),0)),0)} -> 0 | Z11: {=IFERROR(INDEX('Makkah Migration Plan'!$K:$K,MATCH(1,('Makkah Migration Plan'!$Y:$Y=$S24)*('Makkah Migration Plan'!$X:$X=Z$19),0)),0)} -> 0
A12: Batch 06 | B12: {=IFERROR(AVERAGE(_xlfn._xlws.FILTER(IF(TODAY()<'MADINAH Migration Plan-'!$E$2:$E$205,0,IF(TODAY()>='MADINAH Migration Plan-'!$F$2:$F$205,1,NETWORKDAYS.INTL('MADINAH Migration Plan-'!$E$2:$E$205,TODAY(),"0000011")/NETWORKDAYS.INTL('MADINAH Migration Plan-'!$E$2:$E$205,'MADINAH Migration Plan-'!$F$2:$F$205,"0000011"))),('MADINAH Migration Plan-'!$Y$2:$Y$205=$A12)*('MADINAH Migration Plan-'!$E$2:$E$205<>"")*('MADINAH Migration Plan-'!$F$2:$F$205<>""))),0)} -> 0 | C12: =AVERAGE(D12:H12) -> 0 | D12: {=IFERROR(INDEX('MADINAH Migration Plan-'!$K:$K,MATCH(1,('MADINAH Migration Plan-'!$Y:$Y=$A12)*('MADINAH Migration Plan-'!$X:$X=D$6),0)),0)} -> 0 | E12: {=IFERROR(INDEX('MADINAH Migration Plan-'!$K:$K,MATCH(1,('MADINAH Migration Plan-'!$Y:$Y=$A12)*('MADINAH Migration Plan-'!$X:$X=E$6),0)),0)} -> 0 | F12: {=IFERROR(INDEX('MADINAH Migration Plan-'!$K:$K,MATCH(1,('MADINAH Migration Plan-'!$Y:$Y=$A12)*('MADINAH Migration Plan-'!$X:$X=F$6),0)),0)} -> 0 | G12: {=IFERROR(INDEX('MADINAH Migration Plan-'!$K:$K,MATCH(1,('MADINAH Migration Plan-'!$Y:$Y=$A12)*('MADINAH Migration Plan-'!$X:$X=G$6),0)),0)} -> 0 | H12: {=IFERROR(INDEX('MADINAH Migration Plan-'!$K:$K,MATCH(1,('MADINAH Migration Plan-'!$Y:$Y=$A12)*('MADINAH Migration Plan-'!$X:$X=H$6),0)),0)} -> 0 | J12: Batch 06 | K12: {=IFERROR(AVERAGE(_xlfn._xlws.FILTER(IF(TODAY()<'Jeddah Migration Plan'!$E$2:$E$207,0,IF(TODAY()>='Jeddah Migration Plan'!$F$2:$F$207,1,NETWORKDAYS.INTL('Jeddah Migration Plan'!$E$2:$E$207,TODAY(),"0000011")/NETWORKDAYS.INTL('Jeddah Migration Plan'!$E$2:$E$207,'Jeddah Migration Plan'!$F$2:$F$207,"0000011"))),('Jeddah Migration Plan'!$Y$2:$Y$207=$J12)*('Jeddah Migration Plan'!$E$2:$E$207<>"")*('Jeddah Migration Plan'!$F$2:$F$207<>""))),0)} -> 0 | L12: =AVERAGE(M12:Q12) -> 0 | M12: {=IFERROR(INDEX('Jeddah Migration Plan'!$K:$K,MATCH(1,('Jeddah Migration Plan'!$Y:$Y=$J12)*('Jeddah Migration Plan'!$X:$X=M$6),0)),0)} -> 0 | N12: {=IFERROR(INDEX('Jeddah Migration Plan'!$K:$K,MATCH(1,('Jeddah Migration Plan'!$Y:$Y=$J12)*('Jeddah Migration Plan'!$X:$X=N$6),0)),0)} -> 0 | O12: {=IFERROR(INDEX('Jeddah Migration Plan'!$K:$K,MATCH(1,('Jeddah Migration Plan'!$Y:$Y=$J12)*('Jeddah Migration Plan'!$X:$X=O$6),0)),0)} -> 0 | P12: {=IFERROR(INDEX('Jeddah Migration Plan'!$K:$K,MATCH(1,('Jeddah Migration Plan'!$Y:$Y=$J12)*('Jeddah Migration Plan'!$X:$X=P$6),0)),0)} -> 0 | Q12: {=IFERROR(INDEX('Jeddah Migration Plan'!$K:$K,MATCH(1,('Jeddah Migration Plan'!$Y:$Y=$J12)*('Jeddah Migration Plan'!$X:$X=Q$6),0)),0)} -> 0 | S12: Batch 06 | T12: {=IFERROR(AVERAGE(_xlfn._xlws.FILTER(IF(TODAY()<'Makkah Migration Plan'!$E$2:$E$204,0,IF(TODAY()>='Makkah Migration Plan'!$F$2:$F$204,1,NETWORKDAYS.INTL('Makkah Migration Plan'!$E$2:$E$204,TODAY(),"0000011")/NETWORKDAYS.INTL('Makkah Migration Plan'!$E$2:$E$204,'Makkah Migration Plan'!$F$2:$F$204,"0000011"))),('Makkah Migration Plan'!$Y$2:$Y$204=$S12)*('Makkah Migration Plan'!$E$2:$E$204<>"")*('Makkah Migration Plan'!$F$2:$F$204<>""))),0)} -> 0 | U12: =AVERAGE(V12:Z12) -> 0 | V12: {=IFERROR(INDEX('Makkah Migration Plan'!$K:$K,MATCH(1,('Makkah Migration Plan'!$Y:$Y=$S25)*('Makkah Migration Plan'!$X:$X=V$19),0)),0)} -> 0 | W12: {=IFERROR(INDEX('Makkah Migration Plan'!$K:$K,MATCH(1,('Makkah Migration Plan'!$Y:$Y=$S25)*('Makkah Migration Plan'!$X:$X=W$19),0)),0)} -> 0 | X12: {=IFERROR(INDEX('Makkah Migration Plan'!$K:$K,MATCH(1,('Makkah Migration Plan'!$Y:$Y=$S25)*('Makkah Migration Plan'!$X:$X=X$19),0)),0)} -> 0 | Y12: {=IFERROR(INDEX('Makkah Migration Plan'!$K:$K,MATCH(1,('Makkah Migration Plan'!$Y:$Y=$S25)*('Makkah Migration Plan'!$X:$X=Y$19),0)),0)} -> 0 | Z12: {=IFERROR(INDEX('Makkah Migration Plan'!$K:$K,MATCH(1,('Makkah Migration Plan'!$Y:$Y=$S25)*('Makkah Migration Plan'!$X:$X=Z$19),0)),0)} -> 0
A13: Batch 07 | B13: {=IFERROR(AVERAGE(_xlfn._xlws.FILTER(IF(TODAY()<'MADINAH Migration Plan-'!$E$2:$E$205,0,IF(TODAY()>='MADINAH Migration Plan-'!$F$2:$F$205,1,NETWORKDAYS.INTL('MADINAH Migration Plan-'!$E$2:$E$205,TODAY(),"0000011")/NETWORKDAYS.INTL('MADINAH Migration Plan-'!$E$2:$E$205,'MADINAH Migration Plan-'!$F$2:$F$205,"0000011"))),('MADINAH Migration Plan-'!$Y$2:$Y$205=$A13)*('MADINAH Migration Plan-'!$E$2:$E$205<>"")*('MADINAH Migration Plan-'!$F$2:$F$205<>""))),0)} -> 0 | C13: =AVERAGE(D13:H13) -> 0 | D13: {=IFERROR(INDEX('MADINAH Migration Plan-'!$K:$K,MATCH(1,('MADINAH Migration Plan-'!$Y:$Y=$A13)*('MADINAH Migration Plan-'!$X:$X=D$6),0)),0)} -> 0 | E13: {=IFERROR(INDEX('MADINAH Migration Plan-'!$K:$K,MATCH(1,('MADINAH Migration Plan-'!$Y:$Y=$A13)*('MADINAH Migration Plan-'!$X:$X=E$6),0)),0)} -> 0 | F13: {=IFERROR(INDEX('MADINAH Migration Plan-'!$K:$K,MATCH(1,('MADINAH Migration Plan-'!$Y:$Y=$A13)*('MADINAH Migration Plan-'!$X:$X=F$6),0)),0)} -> 0 | G13: {=IFERROR(INDEX('MADINAH Migration Plan-'!$K:$K,MATCH(1,('MADINAH Migration Plan-'!$Y:$Y=$A13)*('MADINAH Migration Plan-'!$X:$X=G$6),0)),0)} -> 0 | H13: {=IFERROR(INDEX('MADINAH Migration Plan-'!$K:$K,MATCH(1,('MADINAH Migration Plan-'!$Y:$Y=$A13)*('MADINAH Migration Plan-'!$X:$X=H$6),0)),0)} -> 0 | J13: Batch 07 | K13: {=IFERROR(AVERAGE(_xlfn._xlws.FILTER(IF(TODAY()<'Jeddah Migration Plan'!$E$2:$E$207,0,IF(TODAY()>='Jeddah Migration Plan'!$F$2:$F$207,1,NETWORKDAYS.INTL('Jeddah Migration Plan'!$E$2:$E$207,TODAY(),"0000011")/NETWORKDAYS.INTL('Jeddah Migration Plan'!$E$2:$E$207,'Jeddah Migration Plan'!$F$2:$F$207,"0000011"))),('Jeddah Migration Plan'!$Y$2:$Y$207=$J13)*('Jeddah Migration Plan'!$E$2:$E$207<>"")*('Jeddah Migration Plan'!$F$2:$F$207<>""))),0)} -> 0 | L13: =AVERAGE(M13:Q13) -> 0 | M13: {=IFERROR(INDEX('Jeddah Migration Plan'!$K:$K,MATCH(1,('Jeddah Migration Plan'!$Y:$Y=$J13)*('Jeddah Migration Plan'!$X:$X=M$6),0)),0)} -> 0 | N13: {=IFERROR(INDEX('Jeddah Migration Plan'!$K:$K,MATCH(1,('Jeddah Migration Plan'!$Y:$Y=$J13)*('Jeddah Migration Plan'!$X:$X=N$6),0)),0)} -> 0 | O13: {=IFERROR(INDEX('Jeddah Migration Plan'!$K:$K,MATCH(1,('Jeddah Migration Plan'!$Y:$Y=$J13)*('Jeddah Migration Plan'!$X:$X=O$6),0)),0)} -> 0 | P13: {=IFERROR(INDEX('Jeddah Migration Plan'!$K:$K,MATCH(1,('Jeddah Migration Plan'!$Y:$Y=$J13)*('Jeddah Migration Plan'!$X:$X=P$6),0)),0)} -> 0 | Q13: {=IFERROR(INDEX('Jeddah Migration Plan'!$K:$K,MATCH(1,('Jeddah Migration Plan'!$Y:$Y=$J13)*('Jeddah Migration Plan'!$X:$X=Q$6),0)),0)} -> 0 | S13: Batch 07 | T13: {=IFERROR(AVERAGE(_xlfn._xlws.FILTER(IF(TODAY()<'Makkah Migration Plan'!$E$2:$E$204,0,IF(TODAY()>='Makkah Migration Plan'!$F$2:$F$204,1,NETWORKDAYS.INTL('Makkah Migration Plan'!$E$2:$E$204,TODAY(),"0000011")/NETWORKDAYS.INTL('Makkah Migration Plan'!$E$2:$E$204,'Makkah Migration Plan'!$F$2:$F$204,"0000011"))),('Makkah Migration Plan'!$Y$2:$Y$204=$S13)*('Makkah Migration Plan'!$E$2:$E$204<>"")*('Makkah Migration Plan'!$F$2:$F$204<>""))),0)} -> 0 | U13: =AVERAGE(V13:Z13) -> 0 | V13: {=IFERROR(INDEX('Makkah Migration Plan'!$K:$K,MATCH(1,('Makkah Migration Plan'!$Y:$Y=$S26)*('Makkah Migration Plan'!$X:$X=V$19),0)),0)} -> 0 | W13: {=IFERROR(INDEX('Makkah Migration Plan'!$K:$K,MATCH(1,('Makkah Migration Plan'!$Y:$Y=$S26)*('Makkah Migration Plan'!$X:$X=W$19),0)),0)} -> 0 | X13: {=IFERROR(INDEX('Makkah Migration Plan'!$K:$K,MATCH(1,('Makkah Migration Plan'!$Y:$Y=$S26)*('Makkah Migration Plan'!$X:$X=X$19),0)),0)} -> 0 | Y13: {=IFERROR(INDEX('Makkah Migration Plan'!$K:$K,MATCH(1,('Makkah Migration Plan'!$Y:$Y=$S26)*('Makkah Migration Plan'!$X:$X=Y$19),0)),0)} -> 0 | Z13: {=IFERROR(INDEX('Makkah Migration Plan'!$K:$K,MATCH(1,('Makkah Migration Plan'!$Y:$Y=$S26)*('Makkah Migration Plan'!$X:$X=Z$19),0)),0)} -> 0
A14: Batch 08 | B14: {=IFERROR(AVERAGE(_xlfn._xlws.FILTER(IF(TODAY()<'MADINAH Migration Plan-'!$E$2:$E$205,0,IF(TODAY()>='MADINAH Migration Plan-'!$F$2:$F$205,1,NETWORKDAYS.INTL('MADINAH Migration Plan-'!$E$2:$E$205,TODAY(),"0000011")/NETWORKDAYS.INTL('MADINAH Migration Plan-'!$E$2:$E$205,'MADINAH Migration Plan-'!$F$2:$F$205,"0000011"))),('MADINAH Migration Plan-'!$Y$2:$Y$205=$A14)*('MADINAH Migration Plan-'!$E$2:$E$205<>"")*('MADINAH Migration Plan-'!$F$2:$F$205<>""))),0)} -> 0 | C14: =AVERAGE(D14:H14) -> 0 | D14: {=IFERROR(INDEX('MADINAH Migration Plan-'!$K:$K,MATCH(1,('MADINAH Migration Plan-'!$Y:$Y=$A14)*('MADINAH Migration Plan-'!$X:$X=D$6),0)),0)} -> 0 | E14: {=IFERROR(INDEX('MADINAH Migration Plan-'!$K:$K,MATCH(1,('MADINAH Migration Plan-'!$Y:$Y=$A14)*('MADINAH Migration Plan-'!$X:$X=E$6),0)),0)} -> 0 | F14: {=IFERROR(INDEX('MADINAH Migration Plan-'!$K:$K,MATCH(1,('MADINAH Migration Plan-'!$Y:$Y=$A14)*('MADINAH Migration Plan-'!$X:$X=F$6),0)),0)} -> 0 | G14: {=IFERROR(INDEX('MADINAH Migration Plan-'!$K:$K,MATCH(1,('MADINAH Migration Plan-'!$Y:$Y=$A14)*('MADINAH Migration Plan-'!$X:$X=G$6),0)),0)} -> 0 | H14: {=IFERROR(INDEX('MADINAH Migration Plan-'!$K:$K,MATCH(1,('MADINAH Migration Plan-'!$Y:$Y=$A14)*('MADINAH Migration Plan-'!$X:$X=H$6),0)),0)} -> 0 | J14: Batch 08 | K14: {=IFERROR(AVERAGE(_xlfn._xlws.FILTER(IF(TODAY()<'Jeddah Migration Plan'!$E$2:$E$207,0,IF(TODAY()>='Jeddah Migration Plan'!$F$2:$F$207,1,NETWORKDAYS.INTL('Jeddah Migration Plan'!$E$2:$E$207,TODAY(),"0000011")/NETWORKDAYS.INTL('Jeddah Migration Plan'!$E$2:$E$207,'Jeddah Migration Plan'!$F$2:$F$207,"0000011"))),('Jeddah Migration Plan'!$Y$2:$Y$207=$J14)*('Jeddah Migration Plan'!$E$2:$E$207<>"")*('Jeddah Migration Plan'!$F$2:$F$207<>""))),0)} -> 0 | L14: =AVERAGE(M14:Q14) -> 0 | M14: {=IFERROR(INDEX('Jeddah Migration Plan'!$K:$K,MATCH(1,('Jeddah Migration Plan'!$Y:$Y=$J14)*('Jeddah Migration Plan'!$X:$X=M$6),0)),0)} -> 0 | N14: {=IFERROR(INDEX('Jeddah Migration Plan'!$K:$K,MATCH(1,('Jeddah Migration Plan'!$Y:$Y=$J14)*('Jeddah Migration Plan'!$X:$X=N$6),0)),0)} -> 0 | O14: {=IFERROR(INDEX('Jeddah Migration Plan'!$K:$K,MATCH(1,('Jeddah Migration Plan'!$Y:$Y=$J14)*('Jeddah Migration Plan'!$X:$X=O$6),0)),0)} -> 0 | P14: {=IFERROR(INDEX('Jeddah Migration Plan'!$K:$K,MATCH(1,('Jeddah Migration Plan'!$Y:$Y=$J14)*('Jeddah Migration Plan'!$X:$X=P$6),0)),0)} -> 0 | Q14: {=IFERROR(INDEX('Jeddah Migration Plan'!$K:$K,MATCH(1,('Jeddah Migration Plan'!$Y:$Y=$J14)*('Jeddah Migration Plan'!$X:$X=Q$6),0)),0)} -> 0 | S14: Batch 08 | T14: {=IFERROR(AVERAGE(_xlfn._xlws.FILTER(IF(TODAY()<'Makkah Migration Plan'!$E$2:$E$204,0,IF(TODAY()>='Makkah Migration Plan'!$F$2:$F$204,1,NETWORKDAYS.INTL('Makkah Migration Plan'!$E$2:$E$204,TODAY(),"0000011")/NETWORKDAYS.INTL('Makkah Migration Plan'!$E$2:$E$204,'Makkah Migration Plan'!$F$2:$F$204,"0000011"))),('Makkah Migration Plan'!$Y$2:$Y$204=$S14)*('Makkah Migration Plan'!$E$2:$E$204<>"")*('Makkah Migration Plan'!$F$2:$F$204<>""))),0)} -> 0 | U14: =AVERAGE(V14:Z14) -> 0 | V14: {=IFERROR(INDEX('Makkah Migration Plan'!$K:$K,MATCH(1,('Makkah Migration Plan'!$Y:$Y=$S27)*('Makkah Migration Plan'!$X:$X=V$19),0)),0)} -> 0 | W14: {=IFERROR(INDEX('Makkah Migration Plan'!$K:$K,MATCH(1,('Makkah Migration Plan'!$Y:$Y=$S27)*('Makkah Migration Plan'!$X:$X=W$19),0)),0)} -> 0 | X14: {=IFERROR(INDEX('Makkah Migration Plan'!$K:$K,MATCH(1,('Makkah Migration Plan'!$Y:$Y=$S27)*('Makkah Migration Plan'!$X:$X=X$19),0)),0)} -> 0 | Y14: {=IFERROR(INDEX('Makkah Migration Plan'!$K:$K,MATCH(1,('Makkah Migration Plan'!$Y:$Y=$S27)*('Makkah Migration Plan'!$X:$X=Y$19),0)),0)} -> 0 | Z14: {=IFERROR(INDEX('Makkah Migration Plan'!$K:$K,MATCH(1,('Makkah Migration Plan'!$Y:$Y=$S27)*('Makkah Migration Plan'!$X:$X=Z$19),0)),0)} -> 0
A15: Batch 09 | B15: {=IFERROR(AVERAGE(_xlfn._xlws.FILTER(IF(TODAY()<'MADINAH Migration Plan-'!$E$2:$E$205,0,IF(TODAY()>='MADINAH Migration Plan-'!$F$2:$F$205,1,NETWORKDAYS.INTL('MADINAH Migration Plan-'!$E$2:$E$205,TODAY(),"0000011")/NETWORKDAYS.INTL('MADINAH Migration Plan-'!$E$2:$E$205,'MADINAH Migration Plan-'!$F$2:$F$205,"0000011"))),('MADINAH Migration Plan-'!$Y$2:$Y$205=$A15)*('MADINAH Migration Plan-'!$E$2:$E$205<>"")*('MADINAH Migration Plan-'!$F$2:$F$205<>""))),0)} -> 0 | C15: =AVERAGE(D15:H15) -> 0 | D15: {=IFERROR(INDEX('MADINAH Migration Plan-'!$K:$K,MATCH(1,('MADINAH Migration Plan-'!$Y:$Y=$A15)*('MADINAH Migration Plan-'!$X:$X=D$6),0)),0)} -> 0 | E15: {=IFERROR(INDEX('MADINAH Migration Plan-'!$K:$K,MATCH(1,('MADINAH Migration Plan-'!$Y:$Y=$A15)*('MADINAH Migration Plan-'!$X:$X=E$6),0)),0)} -> 0 | F15: {=IFERROR(INDEX('MADINAH Migration Plan-'!$K:$K,MATCH(1,('MADINAH Migration Plan-'!$Y:$Y=$A15)*('MADINAH Migration Plan-'!$X:$X=F$6),0)),0)} -> 0 | G15: {=IFERROR(INDEX('MADINAH Migration Plan-'!$K:$K,MATCH(1,('MADINAH Migration Plan-'!$Y:$Y=$A15)*('MADINAH Migration Plan-'!$X:$X=G$6),0)),0)} -> 0 | H15: {=IFERROR(INDEX('MADINAH Migration Plan-'!$K:$K,MATCH(1,('MADINAH Migration Plan-'!$Y:$Y=$A15)*('MADINAH Migration Plan-'!$X:$X=H$6),0)),0)} -> 0 | J15: Batch 09 | K15: {=IFERROR(AVERAGE(_xlfn._xlws.FILTER(IF(TODAY()<'Jeddah Migration Plan'!$E$2:$E$207,0,IF(TODAY()>='Jeddah Migration Plan'!$F$2:$F$207,1,NETWORKDAYS.INTL('Jeddah Migration Plan'!$E$2:$E$207,TODAY(),"0000011")/NETWORKDAYS.INTL('Jeddah Migration Plan'!$E$2:$E$207,'Jeddah Migration Plan'!$F$2:$F$207,"0000011"))),('Jeddah Migration Plan'!$Y$2:$Y$207=$J15)*('Jeddah Migration Plan'!$E$2:$E$207<>"")*('Jeddah Migration Plan'!$F$2:$F$207<>""))),0)} -> 0 | L15: =AVERAGE(M15:Q15) -> 0 | M15: {=IFERROR(INDEX('Jeddah Migration Plan'!$K:$K,MATCH(1,('Jeddah Migration Plan'!$Y:$Y=$J15)*('Jeddah Migration Plan'!$X:$X=M$6),0)),0)} -> 0 | N15: {=IFERROR(INDEX('Jeddah Migration Plan'!$K:$K,MATCH(1,('Jeddah Migration Plan'!$Y:$Y=$J15)*('Jeddah Migration Plan'!$X:$X=N$6),0)),0)} -> 0 | O15: {=IFERROR(INDEX('Jeddah Migration Plan'!$K:$K,MATCH(1,('Jeddah Migration Plan'!$Y:$Y=$J15)*('Jeddah Migration Plan'!$X:$X=O$6),0)),0)} -> 0 | P15: {=IFERROR(INDEX('Jeddah Migration Plan'!$K:$K,MATCH(1,('Jeddah Migration Plan'!$Y:$Y=$J15)*('Jeddah Migration Plan'!$X:$X=P$6),0)),0)} -> 0 | Q15: {=IFERROR(INDEX('Jeddah Migration Plan'!$K:$K,MATCH(1,('Jeddah Migration Plan'!$Y:$Y=$J15)*('Jeddah Migration Plan'!$X:$X=Q$6),0)),0)} -> 0 | S15: Batch 09 | T15: {=IFERROR(AVERAGE(_xlfn._xlws.FILTER(IF(TODAY()<'Makkah Migration Plan'!$E$2:$E$204,0,IF(TODAY()>='Makkah Migration Plan'!$F$2:$F$204,1,NETWORKDAYS.INTL('Makkah Migration Plan'!$E$2:$E$204,TODAY(),"0000011")/NETWORKDAYS.INTL('Makkah Migration Plan'!$E$2:$E$204,'Makkah Migration Plan'!$F$2:$F$204,"0000011"))),('Makkah Migration Plan'!$Y$2:$Y$204=$S15)*('Makkah Migration Plan'!$E$2:$E$204<>"")*('Makkah Migration Plan'!$F$2:$F$204<>""))),0)} -> 0 | U15: =AVERAGE(V15:Z15) -> 0 | V15: {=IFERROR(INDEX('Makkah Migration Plan'!$K:$K,MATCH(1,('Makkah Migration Plan'!$Y:$Y=$S28)*('Makkah Migration Plan'!$X:$X=V$19),0)),0)} -> 0 | W15: {=IFERROR(INDEX('Makkah Migration Plan'!$K:$K,MATCH(1,('Makkah Migration Plan'!$Y:$Y=$S28)*('Makkah Migration Plan'!$X:$X=W$19),0)),0)} -> 0 | X15: {=IFERROR(INDEX('Makkah Migration Plan'!$K:$K,MATCH(1,('Makkah Migration Plan'!$Y:$Y=$S28)*('Makkah Migration Plan'!$X:$X=X$19),0)),0)} -> 0 | Y15: {=IFERROR(INDEX('Makkah Migration Plan'!$K:$K,MATCH(1,('Makkah Migration Plan'!$Y:$Y=$S28)*('Makkah Migration Plan'!$X:$X=Y$19),0)),0)} -> 0 | Z15: {=IFERROR(INDEX('Makkah Migration Plan'!$K:$K,MATCH(1,('Makkah Migration Plan'!$Y:$Y=$S28)*('Makkah Migration Plan'!$X:$X=Z$19),0)),0)} -> 0
A16: Batch 10 | B16: {=IFERROR(AVERAGE(_xlfn._xlws.FILTER(IF(TODAY()<'MADINAH Migration Plan-'!$E$2:$E$205,0,IF(TODAY()>='MADINAH Migration Plan-'!$F$2:$F$205,1,NETWORKDAYS.INTL('MADINAH Migration Plan-'!$E$2:$E$205,TODAY(),"0000011")/NETWORKDAYS.INTL('MADINAH Migration Plan-'!$E$2:$E$205,'MADINAH Migration Plan-'!$F$2:$F$205,"0000011"))),('MADINAH Migration Plan-'!$Y$2:$Y$205=$A16)*('MADINAH Migration Plan-'!$E$2:$E$205<>"")*('MADINAH Migration Plan-'!$F$2:$F$205<>""))),0)} -> 0 | C16: =AVERAGE(D16:H16) -> 0 | D16: {=IFERROR(INDEX('MADINAH Migration Plan-'!$K:$K,MATCH(1,('MADINAH Migration Plan-'!$Y:$Y=$A16)*('MADINAH Migration Plan-'!$X:$X=D$6),0)),0)} -> 0 | E16: {=IFERROR(INDEX('MADINAH Migration Plan-'!$K:$K,MATCH(1,('MADINAH Migration Plan-'!$Y:$Y=$A16)*('MADINAH Migration Plan-'!$X:$X=E$6),0)),0)} -> 0 | F16: {=IFERROR(INDEX('MADINAH Migration Plan-'!$K:$K,MATCH(1,('MADINAH Migration Plan-'!$Y:$Y=$A16)*('MADINAH Migration Plan-'!$X:$X=F$6),0)),0)} -> 0 | G16: {=IFERROR(INDEX('MADINAH Migration Plan-'!$K:$K,MATCH(1,('MADINAH Migration Plan-'!$Y:$Y=$A16)*('MADINAH Migration Plan-'!$X:$X=G$6),0)),0)} -> 0 | H16: {=IFERROR(INDEX('MADINAH Migration Plan-'!$K:$K,MATCH(1,('MADINAH Migration Plan-'!$Y:$Y=$A16)*('MADINAH Migration Plan-'!$X:$X=H$6),0)),0)} -> 0 | J16: Batch 10 | K16: {=IFERROR(AVERAGE(_xlfn._xlws.FILTER(IF(TODAY()<'Jeddah Migration Plan'!$E$2:$E$207,0,IF(TODAY()>='Jeddah Migration Plan'!$F$2:$F$207,1,NETWORKDAYS.INTL('Jeddah Migration Plan'!$E$2:$E$207,TODAY(),"0000011")/NETWORKDAYS.INTL('Jeddah Migration Plan'!$E$2:$E$207,'Jeddah Migration Plan'!$F$2:$F$207,"0000011"))),('Jeddah Migration Plan'!$Y$2:$Y$207=$J16)*('Jeddah Migration Plan'!$E$2:$E$207<>"")*('Jeddah Migration Plan'!$F$2:$F$207<>""))),0)} -> 0 | L16: =AVERAGE(M16:Q16) -> 0 | M16: {=IFERROR(INDEX('Jeddah Migration Plan'!$K:$K,MATCH(1,('Jeddah Migration Plan'!$Y:$Y=$J16)*('Jeddah Migration Plan'!$X:$X=M$6),0)),0)} -> 0 | N16: {=IFERROR(INDEX('Jeddah Migration Plan'!$K:$K,MATCH(1,('Jeddah Migration Plan'!$Y:$Y=$J16)*('Jeddah Migration Plan'!$X:$X=N$6),0)),0)} -> 0 | O16: {=IFERROR(INDEX('Jeddah Migration Plan'!$K:$K,MATCH(1,('Jeddah Migration Plan'!$Y:$Y=$J16)*('Jeddah Migration Plan'!$X:$X=O$6),0)),0)} -> 0 | P16: {=IFERROR(INDEX('Jeddah Migration Plan'!$K:$K,MATCH(1,('Jeddah Migration Plan'!$Y:$Y=$J16)*('Jeddah Migration Plan'!$X:$X=P$6),0)),0)} -> 0 | Q16: {=IFERROR(INDEX('Jeddah Migration Plan'!$K:$K,MATCH(1,('Jeddah Migration Plan'!$Y:$Y=$J16)*('Jeddah Migration Plan'!$X:$X=Q$6),0)),0)} -> 0 | S16: Batch 10 | T16: {=IFERROR(AVERAGE(_xlfn._xlws.FILTER(IF(TODAY()<'Makkah Migration Plan'!$E$2:$E$204,0,IF(TODAY()>='Makkah Migration Plan'!$F$2:$F$204,1,NETWORKDAYS.INTL('Makkah Migration Plan'!$E$2:$E$204,TODAY(),"0000011")/NETWORKDAYS.INTL('Makkah Migration Plan'!$E$2:$E$204,'Makkah Migration Plan'!$F$2:$F$204,"0000011"))),('Makkah Migration Plan'!$Y$2:$Y$204=$S16)*('Makkah Migration Plan'!$E$2:$E$204<>"")*('Makkah Migration Plan'!$F$2:$F$204<>""))),0)} -> 0 | U16: =AVERAGE(V16:Z16) -> 0 | V16: {=IFERROR(INDEX('Makkah Migration Plan'!$K:$K,MATCH(1,('Makkah Migration Plan'!$Y:$Y=$S29)*('Makkah Migration Plan'!$X:$X=V$19),0)),0)} -> 0 | W16: {=IFERROR(INDEX('Makkah Migration Plan'!$K:$K,MATCH(1,('Makkah Migration Plan'!$Y:$Y=$S29)*('Makkah Migration Plan'!$X:$X=W$19),0)),0)} -> 0 | X16: {=IFERROR(INDEX('Makkah Migration Plan'!$K:$K,MATCH(1,('Makkah Migration Plan'!$Y:$Y=$S29)*('Makkah Migration Plan'!$X:$X=X$19),0)),0)} -> 0 | Y16: {=IFERROR(INDEX('Makkah Migration Plan'!$K:$K,MATCH(1,('Makkah Migration Plan'!$Y:$Y=$S29)*('Makkah Migration Plan'!$X:$X=Y$19),0)),0)} -> 0 | Z16: {=IFERROR(INDEX('Makkah Migration Plan'!$K:$K,MATCH(1,('Makkah Migration Plan'!$Y:$Y=$S29)*('Makkah Migration Plan'!$X:$X=Z$19),0)),0)} -> 0
A18: ABHA Upstream Progress | S18: JIZAN Upstream Progress
A19: Batch No. | B19: Planned % | C19: Completed % | D19: SLD Submission | E19: SLD Validation | F19: E2E for Grid SS | G19: E2E Rectification | H19: Cutover | S19: Batch No. | T19: Planned % | U19: Completed % | V19: SLD Submission | W19: SLD Validation | X19: E2E for Grid SS | Y19: E2E Rectification | Z19: Cutover
A20: Batch 01 | B20: {=IFERROR(AVERAGE(_xlfn._xlws.FILTER(IF(TODAY()<'ABHA Migration Plan'!$E$2:$E$205,0,IF(TODAY()>='ABHA Migration Plan'!$F$2:$F$205,1,NETWORKDAYS.INTL('ABHA Migration Plan'!$E$2:$E$205,TODAY(),"0000011")/NETWORKDAYS.INTL('ABHA Migration Plan'!$E$2:$E$205,'ABHA Migration Plan'!$F$2:$F$205,"0000011"))),('ABHA Migration Plan'!$Y$2:$Y$205=$A20)*('ABHA Migration Plan'!$E$2:$E$205<>"")*('ABHA Migration Plan'!$F$2:$F$205<>""))),0)} -> 0.4 | C20: =AVERAGE(D20:H20) -> 0.3 | D20: {=IFERROR(INDEX('ABHA Migration Plan'!$K:$K,MATCH(1,('ABHA Migration Plan'!$Y:$Y=$A20)*('ABHA Migration Plan'!$X:$X=D$19),0)),0)} -> 1 | E20: {=IFERROR(INDEX('ABHA Migration Plan'!$K:$K,MATCH(1,('ABHA Migration Plan'!$Y:$Y=$A20)*('ABHA Migration Plan'!$X:$X=E$19),0)),0)} -> 0.5 | F20: {=IFERROR(INDEX('ABHA Migration Plan'!$K:$K,MATCH(1,('ABHA Migration Plan'!$Y:$Y=$A20)*('ABHA Migration Plan'!$X:$X=F$19),0)),0)} -> 0 | G20: {=IFERROR(INDEX('ABHA Migration Plan'!$K:$K,MATCH(1,('ABHA Migration Plan'!$Y:$Y=$A20)*('ABHA Migration Plan'!$X:$X=G$19),0)),0)} -> 0 | H20: {=IFERROR(INDEX('ABHA Migration Plan'!$K:$K,MATCH(1,('ABHA Migration Plan'!$Y:$Y=$A20)*('ABHA Migration Plan'!$X:$X=H$19),0)),0)} -> 0 | S20: Batch 01 | T20: {=IFERROR(AVERAGE(_xlfn._xlws.FILTER(IF(TODAY()<'Jizan Migration Plan'!$E$2:$E$205,0,IF(TODAY()>='Jizan Migration Plan'!$F$2:$F$205,1,NETWORKDAYS.INTL('Jizan Migration Plan'!$E$2:$E$205,TODAY(),"0000011")/NETWORKDAYS.INTL('Jizan Migration Plan'!$E$2:$E$205,'Jizan Migration Plan'!$F$2:$F$205,"0000011"))),('Jizan Migration Plan'!$Y$2:$Y$205=$S20)*('Jizan Migration Plan'!$E$2:$E$205<>"")*('Jizan Migration Plan'!$F$2:$F$205<>""))),0)} -> 0.4 | U20: =AVERAGE(V20:Z20) -> 0.3 | V20: {=IFERROR(INDEX('Jizan Migration Plan'!$K:$K,MATCH(1,('Jizan Migration Plan'!$Y:$Y=$S20)*('Jizan Migration Plan'!$X:$X=V$19),0)),0)} -> 1 | W20: {=IFERROR(INDEX('Jizan Migration Plan'!$K:$K,MATCH(1,('Jizan Migration Plan'!$Y:$Y=$S20)*('Jizan Migration Plan'!$X:$X=W$19),0)),0)} -> 0.5 | X20: {=IFERROR(INDEX('Jizan Migration Plan'!$K:$K,MATCH(1,('Jizan Migration Plan'!$Y:$Y=$S20)*('Jizan Migration Plan'!$X:$X=X$19),0)),0)} -> 0 | Y20: {=IFERROR(INDEX('Jizan Migration Plan'!$K:$K,MATCH(1,('Jizan Migration Plan'!$Y:$Y=$S20)*('Jizan Migration Plan'!$X:$X=Y$19),0)),0)} -> 0 | Z20: {=IFERROR(INDEX('Jizan Migration Plan'!$K:$K,MATCH(1,('Jizan Migration Plan'!$Y:$Y=$S20)*('Jizan Migration Plan'!$X:$X=Z$19),0)),0)} -> 0
A21: Batch 02 | B21: {=IFERROR(AVERAGE(_xlfn._xlws.FILTER(IF(TODAY()<'ABHA Migration Plan'!$E$2:$E$205,0,IF(TODAY()>='ABHA Migration Plan'!$F$2:$F$205,1,NETWORKDAYS.INTL('ABHA Migration Plan'!$E$2:$E$205,TODAY(),"0000011")/NETWORKDAYS.INTL('ABHA Migration Plan'!$E$2:$E$205,'ABHA Migration Plan'!$F$2:$F$205,"0000011"))),('ABHA Migration Plan'!$Y$2:$Y$205=$A21)*('ABHA Migration Plan'!$E$2:$E$205<>"")*('ABHA Migration Plan'!$F$2:$F$205<>""))),0)} -> 0.4 | C21: =AVERAGE(D21:H21) -> 0.24 | D21: {=IFERROR(INDEX('ABHA Migration Plan'!$K:$K,MATCH(1,('ABHA Migration Plan'!$Y:$Y=$A21)*('ABHA Migration Plan'!$X:$X=D$19),0)),0)} -> 1 | E21: {=IFERROR(INDEX('ABHA Migration Plan'!$K:$K,MATCH(1,('ABHA Migration Plan'!$Y:$Y=$A21)*('ABHA Migration Plan'!$X:$X=E$19),0)),0)} -> 0.2 | F21: {=IFERROR(INDEX('ABHA Migration Plan'!$K:$K,MATCH(1,('ABHA Migration Plan'!$Y:$Y=$A21)*('ABHA Migration Plan'!$X:$X=F$19),0)),0)} -> 0 | G21: {=IFERROR(INDEX('ABHA Migration Plan'!$K:$K,MATCH(1,('ABHA Migration Plan'!$Y:$Y=$A21)*('ABHA Migration Plan'!$X:$X=G$19),0)),0)} -> 0 | H21: {=IFERROR(INDEX('ABHA Migration Plan'!$K:$K,MATCH(1,('ABHA Migration Plan'!$Y:$Y=$A21)*('ABHA Migration Plan'!$X:$X=H$19),0)),0)} -> 0 | S21: Batch 02 | T21: {=IFERROR(AVERAGE(_xlfn._xlws.FILTER(IF(TODAY()<'Jizan Migration Plan'!$E$2:$E$205,0,IF(TODAY()>='Jizan Migration Plan'!$F$2:$F$205,1,NETWORKDAYS.INTL('Jizan Migration Plan'!$E$2:$E$205,TODAY(),"0000011")/NETWORKDAYS.INTL('Jizan Migration Plan'!$E$2:$E$205,'Jizan Migration Plan'!$F$2:$F$205,"0000011"))),('Jizan Migration Plan'!$Y$2:$Y$205=$S21)*('Jizan Migration Plan'!$E$2:$E$205<>"")*('Jizan Migration Plan'!$F$2:$F$205<>""))),0)} -> 0 | U21: =AVERAGE(V21:Z21) -> 0.24 | V21: {=IFERROR(INDEX('Jizan Migration Plan'!$K:$K,MATCH(1,('Jizan Migration Plan'!$Y:$Y=$S21)*('Jizan Migration Plan'!$X:$X=V$19),0)),0)} -> 1 | W21: {=IFERROR(INDEX('Jizan Migration Plan'!$K:$K,MATCH(1,('Jizan Migration Plan'!$Y:$Y=$S21)*('Jizan Migration Plan'!$X:$X=W$19),0)),0)} -> 0.2 | X21: {=IFERROR(INDEX('Jizan Migration Plan'!$K:$K,MATCH(1,('Jizan Migration Plan'!$Y:$Y=$S21)*('Jizan Migration Plan'!$X:$X=X$19),0)),0)} -> 0 | Y21: {=IFERROR(INDEX('Jizan Migration Plan'!$K:$K,MATCH(1,('Jizan Migration Plan'!$Y:$Y=$S21)*('Jizan Migration Plan'!$X:$X=Y$19),0)),0)} -> 0 | Z21: {=IFERROR(INDEX('Jizan Migration Plan'!$K:$K,MATCH(1,('Jizan Migration Plan'!$Y:$Y=$S21)*('Jizan Migration Plan'!$X:$X=Z$19),0)),0)} -> 0
A22: Batch 03 | B22: {=IFERROR(AVERAGE(_xlfn._xlws.FILTER(IF(TODAY()<'ABHA Migration Plan'!$E$2:$E$205,0,IF(TODAY()>='ABHA Migration Plan'!$F$2:$F$205,1,NETWORKDAYS.INTL('ABHA Migration Plan'!$E$2:$E$205,TODAY(),"0000011")/NETWORKDAYS.INTL('ABHA Migration Plan'!$E$2:$E$205,'ABHA Migration Plan'!$F$2:$F$205,"0000011"))),('ABHA Migration Plan'!$Y$2:$Y$205=$A22)*('ABHA Migration Plan'!$E$2:$E$205<>"")*('ABHA Migration Plan'!$F$2:$F$205<>""))),0)} -> 0.2 | C22: =AVERAGE(D22:H22) -> 0.2 | D22: {=IFERROR(INDEX('ABHA Migration Plan'!$K:$K,MATCH(1,('ABHA Migration Plan'!$Y:$Y=$A22)*('ABHA Migration Plan'!$X:$X=D$19),0)),0)} -> 1 | E22: {=IFERROR(INDEX('ABHA Migration Plan'!$K:$K,MATCH(1,('ABHA Migration Plan'!$Y:$Y=$A22)*('ABHA Migration Plan'!$X:$X=E$19),0)),0)} -> 0 | F22: {=IFERROR(INDEX('ABHA Migration Plan'!$K:$K,MATCH(1,('ABHA Migration Plan'!$Y:$Y=$A22)*('ABHA Migration Plan'!$X:$X=F$19),0)),0)} -> 0 | G22: {=IFERROR(INDEX('ABHA Migration Plan'!$K:$K,MATCH(1,('ABHA Migration Plan'!$Y:$Y=$A22)*('ABHA Migration Plan'!$X:$X=G$19),0)),0)} -> 0 | H22: {=IFERROR(INDEX('ABHA Migration Plan'!$K:$K,MATCH(1,('ABHA Migration Plan'!$Y:$Y=$A22)*('ABHA Migration Plan'!$X:$X=H$19),0)),0)} -> 0 | S22: Batch 03 | T22: {=IFERROR(AVERAGE(_xlfn._xlws.FILTER(IF(TODAY()<'Jizan Migration Plan'!$E$2:$E$205,0,IF(TODAY()>='Jizan Migration Plan'!$F$2:$F$205,1,NETWORKDAYS.INTL('Jizan Migration Plan'!$E$2:$E$205,TODAY(),"0000011")/NETWORKDAYS.INTL('Jizan Migration Plan'!$E$2:$E$205,'Jizan Migration Plan'!$F$2:$F$205,"0000011"))),('Jizan Migration Plan'!$Y$2:$Y$205=$S22)*('Jizan Migration Plan'!$E$2:$E$205<>"")*('Jizan Migration Plan'!$F$2:$F$205<>""))),0)} -> 0.2 | U22: =AVERAGE(V22:Z22) -> 0.18 | V22: {=IFERROR(INDEX('Jizan Migration Plan'!$K:$K,MATCH(1,('Jizan Migration Plan'!$Y:$Y=$S22)*('Jizan Migration Plan'!$X:$X=V$19),0)),0)} -> 0.9 | W22: {=IFERROR(INDEX('Jizan Migration Plan'!$K:$K,MATCH(1,('Jizan Migration Plan'!$Y:$Y=$S22)*('Jizan Migration Plan'!$X:$X=W$19),0)),0)} -> 0 | X22: {=IFERROR(INDEX('Jizan Migration Plan'!$K:$K,MATCH(1,('Jizan Migration Plan'!$Y:$Y=$S22)*('Jizan Migration Plan'!$X:$X=X$19),0)),0)} -> 0 | Y22: {=IFERROR(INDEX('Jizan Migration Plan'!$K:$K,MATCH(1,('Jizan Migration Plan'!$Y:$Y=$S22)*('Jizan Migration Plan'!$X:$X=Y$19),0)),0)} -> 0 | Z22: {=IFERROR(INDEX('Jizan Migration Plan'!$K:$K,MATCH(1,('Jizan Migration Plan'!$Y:$Y=$S22)*('Jizan Migration Plan'!$X:$X=Z$19),0)),0)} -> 0
A23: Batch 04 | B23: {=IFERROR(AVERAGE(_xlfn._xlws.FILTER(IF(TODAY()<'ABHA Migration Plan'!$E$2:$E$205,0,IF(TODAY()>='ABHA Migration Plan'!$F$2:$F$205,1,NETWORKDAYS.INTL('ABHA Migration Plan'!$E$2:$E$205,TODAY(),"0000011")/NETWORKDAYS.INTL('ABHA Migration Plan'!$E$2:$E$205,'ABHA Migration Plan'!$F$2:$F$205,"0000011"))),('ABHA Migration Plan'!$Y$2:$Y$205=$A23)*('ABHA Migration Plan'!$E$2:$E$205<>"")*('ABHA Migration Plan'!$F$2:$F$205<>""))),0)} -> 0.2 | C23: =AVERAGE(D23:H23) -> 0.18 | D23: {=IFERROR(INDEX('ABHA Migration Plan'!$K:$K,MATCH(1,('ABHA Migration Plan'!$Y:$Y=$A23)*('ABHA Migration Plan'!$X:$X=D$19),0)),0)} -> 0.9 | E23: {=IFERROR(INDEX('ABHA Migration Plan'!$K:$K,MATCH(1,('ABHA Migration Plan'!$Y:$Y=$A23)*('ABHA Migration Plan'!$X:$X=E$19),0)),0)} -> 0 | F23: {=IFERROR(INDEX('ABHA Migration Plan'!$K:$K,MATCH(1,('ABHA Migration Plan'!$Y:$Y=$A23)*('ABHA Migration Plan'!$X:$X=F$19),0)),0)} -> 0 | G23: {=IFERROR(INDEX('ABHA Migration Plan'!$K:$K,MATCH(1,('ABHA Migration Plan'!$Y:$Y=$A23)*('ABHA Migration Plan'!$X:$X=G$19),0)),0)} -> 0 | H23: {=IFERROR(INDEX('ABHA Migration Plan'!$K:$K,MATCH(1,('ABHA Migration Plan'!$Y:$Y=$A23)*('ABHA Migration Plan'!$X:$X=H$19),0)),0)} -> 0 | S23: Batch 04 | T23: {=IFERROR(AVERAGE(_xlfn._xlws.FILTER(IF(TODAY()<'Jizan Migration Plan'!$E$2:$E$205,0,IF(TODAY()>='Jizan Migration Plan'!$F$2:$F$205,1,NETWORKDAYS.INTL('Jizan Migration Plan'!$E$2:$E$205,TODAY(),"0000011")/NETWORKDAYS.INTL('Jizan Migration Plan'!$E$2:$E$205,'Jizan Migration Plan'!$F$2:$F$205,"0000011"))),('Jizan Migration Plan'!$Y$2:$Y$205=$S23)*('Jizan Migration Plan'!$E$2:$E$205<>"")*('Jizan Migration Plan'!$F$2:$F$205<>""))),0)} -> 0 | U23: =AVERAGE(V23:Z23) -> 0 | V23: {=IFERROR(INDEX('Jizan Migration Plan'!$K:$K,MATCH(1,('Jizan Migration Plan'!$Y:$Y=$S23)*('Jizan Migration Plan'!$X:$X=V$19),0)),0)} -> 0 | W23: {=IFERROR(INDEX('Jizan Migration Plan'!$K:$K,MATCH(1,('Jizan Migration Plan'!$Y:$Y=$S23)*('Jizan Migration Plan'!$X:$X=W$19),0)),0)} -> 0 | X23: {=IFERROR(INDEX('Jizan Migration Plan'!$K:$K,MATCH(1,('Jizan Migration Plan'!$Y:$Y=$S23)*('Jizan Migration Plan'!$X:$X=X$19),0)),0)} -> 0 | Y23: {=IFERROR(INDEX('Jizan Migration Plan'!$K:$K,MATCH(1,('Jizan Migration Plan'!$Y:$Y=$S23)*('Jizan Migration Plan'!$X:$X=Y$19),0)),0)} -> 0 | Z23: {=IFERROR(INDEX('Jizan Migration Plan'!$K:$K,MATCH(1,('Jizan Migration Plan'!$Y:$Y=$S23)*('Jizan Migration Plan'!$X:$X=Z$19),0)),0)} -> 0
A24: Batch 05 | B24: {=IFERROR(AVERAGE(_xlfn._xlws.FILTER(IF(TODAY()<'ABHA Migration Plan'!$E$2:$E$205,0,IF(TODAY()>='ABHA Migration Plan'!$F$2:$F$205,1,NETWORKDAYS.INTL('ABHA Migration Plan'!$E$2:$E$205,TODAY(),"0000011")/NETWORKDAYS.INTL('ABHA Migration Plan'!$E$2:$E$205,'ABHA Migration Plan'!$F$2:$F$205,"0000011"))),('ABHA Migration Plan'!$Y$2:$Y$205=$A24)*('ABHA Migration Plan'!$E$2:$E$205<>"")*('ABHA Migration Plan'!$F$2:$F$205<>""))),0)} -> 0 | C24: =AVERAGE(D24:H24) -> 0 | D24: {=IFERROR(INDEX('ABHA Migration Plan'!$K:$K,MATCH(1,('ABHA Migration Plan'!$Y:$Y=$A24)*('ABHA Migration Plan'!$X:$X=D$19),0)),0)} -> 0 | E24: {=IFERROR(INDEX('ABHA Migration Plan'!$K:$K,MATCH(1,('ABHA Migration Plan'!$Y:$Y=$A24)*('ABHA Migration Plan'!$X:$X=E$19),0)),0)} -> 0 | F24: {=IFERROR(INDEX('ABHA Migration Plan'!$K:$K,MATCH(1,('ABHA Migration Plan'!$Y:$Y=$A24)*('ABHA Migration Plan'!$X:$X=F$19),0)),0)} -> 0 | G24: {=IFERROR(INDEX('ABHA Migration Plan'!$K:$K,MATCH(1,('ABHA Migration Plan'!$Y:$Y=$A24)*('ABHA Migration Plan'!$X:$X=G$19),0)),0)} -> 0 | H24: {=IFERROR(INDEX('ABHA Migration Plan'!$K:$K,MATCH(1,('ABHA Migration Plan'!$Y:$Y=$A24)*('ABHA Migration Plan'!$X:$X=H$19),0)),0)} -> 0 | S24: Batch 05 | T24: {=IFERROR(AVERAGE(_xlfn._xlws.FILTER(IF(TODAY()<'Jizan Migration Plan'!$E$2:$E$205,0,IF(TODAY()>='Jizan Migration Plan'!$F$2:$F$205,1,NETWORKDAYS.INTL('Jizan Migration Plan'!$E$2:$E$205,TODAY(),"0000011")/NETWORKDAYS.INTL('Jizan Migration Plan'!$E$2:$E$205,'Jizan Migration Plan'!$F$2:$F$205,"0000011"))),('Jizan Migration Plan'!$Y$2:$Y$205=$S24)*('Jizan Migration Plan'!$E$2:$E$205<>"")*('Jizan Migration Plan'!$F$2:$F$205<>""))),0)} -> 0 | U24: =AVERAGE(V24:Z24) -> 0 | V24: {=IFERROR(INDEX('Jizan Migration Plan'!$K:$K,MATCH(1,('Jizan Migration Plan'!$Y:$Y=$S24)*('Jizan Migration Plan'!$X:$X=V$19),0)),0)} -> 0 | W24: {=IFERROR(INDEX('Jizan Migration Plan'!$K:$K,MATCH(1,('Jizan Migration Plan'!$Y:$Y=$S24)*('Jizan Migration Plan'!$X:$X=W$19),0)),0)} -> 0 | X24: {=IFERROR(INDEX('Jizan Migration Plan'!$K:$K,MATCH(1,('Jizan Migration Plan'!$Y:$Y=$S24)*('Jizan Migration Plan'!$X:$X=X$19),0)),0)} -> 0 | Y24: {=IFERROR(INDEX('Jizan Migration Plan'!$K:$K,MATCH(1,('Jizan Migration Plan'!$Y:$Y=$S24)*('Jizan Migration Plan'!$X:$X=Y$19),0)),0)} -> 0 | Z24: {=IFERROR(INDEX('Jizan Migration Plan'!$K:$K,MATCH(1,('Jizan Migration Plan'!$Y:$Y=$S24)*('Jizan Migration Plan'!$X:$X=Z$19),0)),0)} -> 0
A25: Batch 06 | B25: {=IFERROR(AVERAGE(_xlfn._xlws.FILTER(IF(TODAY()<'ABHA Migration Plan'!$E$2:$E$205,0,IF(TODAY()>='ABHA Migration Plan'!$F$2:$F$205,1,NETWORKDAYS.INTL('ABHA Migration Plan'!$E$2:$E$205,TODAY(),"0000011")/NETWORKDAYS.INTL('ABHA Migration Plan'!$E$2:$E$205,'ABHA Migration Plan'!$F$2:$F$205,"0000011"))),('ABHA Migration Plan'!$Y$2:$Y$205=$A25)*('ABHA Migration Plan'!$E$2:$E$205<>"")*('ABHA Migration Plan'!$F$2:$F$205<>""))),0)} -> 0 | C25: =AVERAGE(D25:H25) -> 0 | D25: {=IFERROR(INDEX('ABHA Migration Plan'!$K:$K,MATCH(1,('ABHA Migration Plan'!$Y:$Y=$A25)*('ABHA Migration Plan'!$X:$X=D$19),0)),0)} -> 0 | E25: {=IFERROR(INDEX('ABHA Migration Plan'!$K:$K,MATCH(1,('ABHA Migration Plan'!$Y:$Y=$A25)*('ABHA Migration Plan'!$X:$X=E$19),0)),0)} -> 0 | F25: {=IFERROR(INDEX('ABHA Migration Plan'!$K:$K,MATCH(1,('ABHA Migration Plan'!$Y:$Y=$A25)*('ABHA Migration Plan'!$X:$X=F$19),0)),0)} -> 0 | G25: {=IFERROR(INDEX('ABHA Migration Plan'!$K:$K,MATCH(1,('ABHA Migration Plan'!$Y:$Y=$A25)*('ABHA Migration Plan'!$X:$X=G$19),0)),0)} -> 0 | H25: {=IFERROR(INDEX('ABHA Migration Plan'!$K:$K,MATCH(1,('ABHA Migration Plan'!$Y:$Y=$A25)*('ABHA Migration Plan'!$X:$X=H$19),0)),0)} -> 0 | S25: Batch 06 | T25: {=IFERROR(AVERAGE(_xlfn._xlws.FILTER(IF(TODAY()<'Jizan Migration Plan'!$E$2:$E$205,0,IF(TODAY()>='Jizan Migration Plan'!$F$2:$F$205,1,NETWORKDAYS.INTL('Jizan Migration Plan'!$E$2:$E$205,TODAY(),"0000011")/NETWORKDAYS.INTL('Jizan Migration Plan'!$E$2:$E$205,'Jizan Migration Plan'!$F$2:$F$205,"0000011"))),('Jizan Migration Plan'!$Y$2:$Y$205=$S25)*('Jizan Migration Plan'!$E$2:$E$205<>"")*('Jizan Migration Plan'!$F$2:$F$205<>""))),0)} -> 0 | U25: =AVERAGE(V25:Z25) -> 0 | V25: {=IFERROR(INDEX('Jizan Migration Plan'!$K:$K,MATCH(1,('Jizan Migration Plan'!$Y:$Y=$S25)*('Jizan Migration Plan'!$X:$X=V$19),0)),0)} -> 0 | W25: {=IFERROR(INDEX('Jizan Migration Plan'!$K:$K,MATCH(1,('Jizan Migration Plan'!$Y:$Y=$S25)*('Jizan Migration Plan'!$X:$X=W$19),0)),0)} -> 0 | X25: {=IFERROR(INDEX('Jizan Migration Plan'!$K:$K,MATCH(1,('Jizan Migration Plan'!$Y:$Y=$S25)*('Jizan Migration Plan'!$X:$X=X$19),0)),0)} -> 0 | Y25: {=IFERROR(INDEX('Jizan Migration Plan'!$K:$K,MATCH(1,('Jizan Migration Plan'!$Y:$Y=$S25)*('Jizan Migration Plan'!$X:$X=Y$19),0)),0)} -> 0 | Z25: {=IFERROR(INDEX('Jizan Migration Plan'!$K:$K,MATCH(1,('Jizan Migration Plan'!$Y:$Y=$S25)*('Jizan Migration Plan'!$X:$X=Z$19),0)),0)} -> 0
A26: Batch 07 | B26: {=IFERROR(AVERAGE(_xlfn._xlws.FILTER(IF(TODAY()<'ABHA Migration Plan'!$E$2:$E$205,0,IF(TODAY()>='ABHA Migration Plan'!$F$2:$F$205,1,NETWORKDAYS.INTL('ABHA Migration Plan'!$E$2:$E$205,TODAY(),"0000011")/NETWORKDAYS.INTL('ABHA Migration Plan'!$E$2:$E$205,'ABHA Migration Plan'!$F$2:$F$205,"0000011"))),('ABHA Migration Plan'!$Y$2:$Y$205=$A26)*('ABHA Migration Plan'!$E$2:$E$205<>"")*('ABHA Migration Plan'!$F$2:$F$205<>""))),0)} -> 0 | C26: =AVERAGE(D26:H26) -> 0 | D26: {=IFERROR(INDEX('ABHA Migration Plan'!$K:$K,MATCH(1,('ABHA Migration Plan'!$Y:$Y=$A26)*('ABHA Migration Plan'!$X:$X=D$19),0)),0)} -> 0 | E26: {=IFERROR(INDEX('ABHA Migration Plan'!$K:$K,MATCH(1,('ABHA Migration Plan'!$Y:$Y=$A26)*('ABHA Migration Plan'!$X:$X=E$19),0)),0)} -> 0 | F26: {=IFERROR(INDEX('ABHA Migration Plan'!$K:$K,MATCH(1,('ABHA Migration Plan'!$Y:$Y=$A26)*('ABHA Migration Plan'!$X:$X=F$19),0)),0)} -> 0 | G26: {=IFERROR(INDEX('ABHA Migration Plan'!$K:$K,MATCH(1,('ABHA Migration Plan'!$Y:$Y=$A26)*('ABHA Migration Plan'!$X:$X=G$19),0)),0)} -> 0 | H26: {=IFERROR(INDEX('ABHA Migration Plan'!$K:$K,MATCH(1,('ABHA Migration Plan'!$Y:$Y=$A26)*('ABHA Migration Plan'!$X:$X=H$19),0)),0)} -> 0 | S26: Batch 07 | T26: {=IFERROR(AVERAGE(_xlfn._xlws.FILTER(IF(TODAY()<'Jizan Migration Plan'!$E$2:$E$205,0,IF(TODAY()>='Jizan Migration Plan'!$F$2:$F$205,1,NETWORKDAYS.INTL('Jizan Migration Plan'!$E$2:$E$205,TODAY(),"0000011")/NETWORKDAYS.INTL('Jizan Migration Plan'!$E$2:$E$205,'Jizan Migration Plan'!$F$2:$F$205,"0000011"))),('Jizan Migration Plan'!$Y$2:$Y$205=$S26)*('Jizan Migration Plan'!$E$2:$E$205<>"")*('Jizan Migration Plan'!$F$2:$F$205<>""))),0)} -> 0 | U26: =AVERAGE(V26:Z26) -> 0 | V26: {=IFERROR(INDEX('Jizan Migration Plan'!$K:$K,MATCH(1,('Jizan Migration Plan'!$Y:$Y=$S26)*('Jizan Migration Plan'!$X:$X=V$19),0)),0)} -> 0 | W26: {=IFERROR(INDEX('Jizan Migration Plan'!$K:$K,MATCH(1,('Jizan Migration Plan'!$Y:$Y=$S26)*('Jizan Migration Plan'!$X:$X=W$19),0)),0)} -> 0 | X26: {=IFERROR(INDEX('Jizan Migration Plan'!$K:$K,MATCH(1,('Jizan Migration Plan'!$Y:$Y=$S26)*('Jizan Migration Plan'!$X:$X=X$19),0)),0)} -> 0 | Y26: {=IFERROR(INDEX('Jizan Migration Plan'!$K:$K,MATCH(1,('Jizan Migration Plan'!$Y:$Y=$S26)*('Jizan Migration Plan'!$X:$X=Y$19),0)),0)} -> 0 | Z26: {=IFERROR(INDEX('Jizan Migration Plan'!$K:$K,MATCH(1,('Jizan Migration Plan'!$Y:$Y=$S26)*('Jizan Migration Plan'!$X:$X=Z$19),0)),0)} -> 0
A27: Batch 08 | B27: {=IFERROR(AVERAGE(_xlfn._xlws.FILTER(IF(TODAY()<'ABHA Migration Plan'!$E$2:$E$205,0,IF(TODAY()>='ABHA Migration Plan'!$F$2:$F$205,1,NETWORKDAYS.INTL('ABHA Migration Plan'!$E$2:$E$205,TODAY(),"0000011")/NETWORKDAYS.INTL('ABHA Migration Plan'!$E$2:$E$205,'ABHA Migration Plan'!$F$2:$F$205,"0000011"))),('ABHA Migration Plan'!$Y$2:$Y$205=$A27)*('ABHA Migration Plan'!$E$2:$E$205<>"")*('ABHA Migration Plan'!$F$2:$F$205<>""))),0)} -> 0 | C27: =AVERAGE(D27:H27) -> 0 | D27: {=IFERROR(INDEX('ABHA Migration Plan'!$K:$K,MATCH(1,('ABHA Migration Plan'!$Y:$Y=$A27)*('ABHA Migration Plan'!$X:$X=D$19),0)),0)} -> 0 | E27: {=IFERROR(INDEX('ABHA Migration Plan'!$K:$K,MATCH(1,('ABHA Migration Plan'!$Y:$Y=$A27)*('ABHA Migration Plan'!$X:$X=E$19),0)),0)} -> 0 | F27: {=IFERROR(INDEX('ABHA Migration Plan'!$K:$K,MATCH(1,('ABHA Migration Plan'!$Y:$Y=$A27)*('ABHA Migration Plan'!$X:$X=F$19),0)),0)} -> 0 | G27: {=IFERROR(INDEX('ABHA Migration Plan'!$K:$K,MATCH(1,('ABHA Migration Plan'!$Y:$Y=$A27)*('ABHA Migration Plan'!$X:$X=G$19),0)),0)} -> 0 | H27: {=IFERROR(INDEX('ABHA Migration Plan'!$K:$K,MATCH(1,('ABHA Migration Plan'!$Y:$Y=$A27)*('ABHA Migration Plan'!$X:$X=H$19),0)),0)} -> 0 | S27: Batch 08 | T27: {=IFERROR(AVERAGE(_xlfn._xlws.FILTER(IF(TODAY()<'Jizan Migration Plan'!$E$2:$E$205,0,IF(TODAY()>='Jizan Migration Plan'!$F$2:$F$205,1,NETWORKDAYS.INTL('Jizan Migration Plan'!$E$2:$E$205,TODAY(),"0000011")/NETWORKDAYS.INTL('Jizan Migration Plan'!$E$2:$E$205,'Jizan Migration Plan'!$F$2:$F$205,"0000011"))),('Jizan Migration Plan'!$Y$2:$Y$205=$S27)*('Jizan Migration Plan'!$E$2:$E$205<>"")*('Jizan Migration Plan'!$F$2:$F$205<>""))),0)} -> 0 | U27: =AVERAGE(V27:Z27) -> 0 | V27: {=IFERROR(INDEX('Jizan Migration Plan'!$K:$K,MATCH(1,('Jizan Migration Plan'!$Y:$Y=$S27)*('Jizan Migration Plan'!$X:$X=V$19),0)),0)} -> 0 | W27: {=IFERROR(INDEX('Jizan Migration Plan'!$K:$K,MATCH(1,('Jizan Migration Plan'!$Y:$Y=$S27)*('Jizan Migration Plan'!$X:$X=W$19),0)),0)} -> 0 | X27: {=IFERROR(INDEX('Jizan Migration Plan'!$K:$K,MATCH(1,('Jizan Migration Plan'!$Y:$Y=$S27)*('Jizan Migration Plan'!$X:$X=X$19),0)),0)} -> 0 | Y27: {=IFERROR(INDEX('Jizan Migration Plan'!$K:$K,MATCH(1,('Jizan Migration Plan'!$Y:$Y=$S27)*('Jizan Migration Plan'!$X:$X=Y$19),0)),0)} -> 0 | Z27: {=IFERROR(INDEX('Jizan Migration Plan'!$K:$K,MATCH(1,('Jizan Migration Plan'!$Y:$Y=$S27)*('Jizan Migration Plan'!$X:$X=Z$19),0)),0)} -> 0

Sheet Summary Dates Option 01 &02
C2: Western Region - Upstream | L2: Southern Region -Upstream
C8: MADINAH | F8: JEDDAH | I8: MAKKAH | L8: ABHA | O8: JIZAN
C9: E2E & Cutover (Grid SS) (Option 01) | D9: Cutover Option 02 (Live on) | F9: E2E & Cutover (Grid SS) (Option 01) | G9: Cutover Option 02 (Live on) | I9: E2E & Cutover (Grid SS) (Option 01) | J9: Cutover Option 02 (Live on) | L9: E2E & Cutover (Grid SS) (Option 01) | M9: Cutover Option 02 (Live on) | O9: E2E & Cutover (Grid SS) (Option 01) | P9: Cutover Option 02 (Live on)
C10: Planned Finish Dates | D10: Planned Finish Dates | F10: Planned Finish Dates | G10: Planned Finish Dates | I10: Planned Finish Dates | J10: Planned Finish Dates | L10: Planned Finish Dates | M10: Planned Finish Dates | O10: Planned Finish Dates | P10: Planned Finish Dates
